Workbook

Sheet Instructions
B2: Marine Fish Marketing Survey - Data Entry Workbook
B3: MS-499 term paper - marketing system of commercially important marine fish species, Chattogram region. Fill only YELLOW cells; BLUE columns calculate themselves; GREY cells are prefilled codes.
B5: 1. Sheet map
B6: Progress_Dashboard | C6: Collected vs target counts per market and actor class - updates by itself, never type here.
B7: Data_Collection_Log | C7: One row per field visit: date, market, collector, session, reference-day flag, interviews done.
B8: Unit_Converter | C8: Type a maund value and read kilograms (and the reverse) using 1 maund = 37.32 kg.
B9: Codebook_Species / Codebook_Markets | C9: Official codes S01-S10 and M1-M6. Use codes everywhere; keep these sheets unchanged.
B10: Form_A_Aratdar / Form_B_Bepari_Faria / Form_R_Khuchra | C10: Trader questionnaires - one respondent per row, IDs already assigned (M1-A-01 ... M6-C-06).
B11: Form_C_Consumer | C11: Exit-intercept consumer slips - one respondent per row.
B12: Price_Observations | C12: CORE dataset: one row per respondent x species quote (buy and sell price, quantity). This sheet feeds the R analysis.
B13: Consumer_Purchases_Focal / Consumer_Other_Fish | C13: Form C species grid and 'any other fish bought' answers, long format.
B14: Form_M_Market_Observation | C14: One row per market - the 12-item infrastructure checklist with evidence source.
B15: Tag_Price_Sheet | C15: Optional displayed-price log (appendix only, not used in hypothesis tests).
B16: QC_Check | C16: Automatic quality flags: duplicates, % sums, missing units, PairID linkage. Review after every entry session.
B18: 2. Price-cell flags (all price columns)
B19: Number (e.g. 850) | C19: BDT price under today's fresh, ice-touched, whole-fish condition.
B20: K | C20: Respondent did not handle this species today.
B21: D | C21: Respondent declined to disclose the price.
B22: 0 and '-' | C22: 0 = true zero (rare); '-' = not applicable. Never leave a species cell empty.
B24: 3. Units, IDs and percentages
B25: Units | C25: Enter the price exactly as quoted (Raw) and pick the unit. Traders usually quote per MAUND (1 maund = 37.32 kg), consumers per KG. The BLUE BDT_per_kg columns convert automatically - do not type in them.
B26: Respondent_ID | C26: Prefilled: {Market}-{Actor}-{Serial}, e.g. M1-A-01, M2-B-05, M3-R-12, M4-C-03. Actor codes: A = aratdar, B = bepari/faria, R = khuchra retailer, C = consumer.
B27: Pair_ID | C27: When a buyer and the matching seller are BOTH interviewed, write the same Pair_ID (e.g. PAIR-001) on both rows. Used for the Wilcoxon signed-rank consistency check.
B28: Percent columns | C28: Enter plain numbers 0-100 (70 means 70%). Cash + MFS + Credit should sum to 100 - QC_Check flags mismatches.
B30: 4. Example entries (illustrations only - do not paste)
B31: Form_A row: | C31: M1-A-01 | M1 | 05/03/2026 | age 46 | Secondary | 18 yrs business | 12 Maund/day | family 6 | rent: Pay, 48000 Yearly | commission: 2.5 Percent | waste 500 Monthly | 6 workers x 700 BDT | storage 2500 Yearly | payment 85 / 10 / 5 | MFS: Regular | problems: ice price, toll, unsold loss
B32: Price_Observations rows: | C32: PO-0001 | M1-A-01 | M1 | Aratdar | S01 | buy 32000 Maund, sell 33500 Maund -> auto 857.45 / 897.64 BDT/kg | qty 8 Maund PO-0002 | M3-R-04 | M3 | Retailer | S06 | buy 240 Kg, sell K (no sale today) | qty 15 Kg
B34: Version 2026-08 | Built for the Methodology V4 instrument battery (Forms A, B, R, M, C + optional tag-price sheet).
B36: সংস্করণ ২ (আপডেট) — ফর্ম-নির্ভুল পরিবর্তন
C37: Form_A: বিদ্যুৎ বিল (Electricity_bill_BDT) ও যন্ত্রাংশ/কুল রক্ষণাবেক্ষণ (Equipment_Cooler_Maintenance_BDT) কলাম সঠিক নামে ঠিক করা হয়েছে।
C38: Form_B: দৈনিক হ্যান্ডেল (কেজি/দিন) কলাম যোগ হয়েছে (আগে বাদ ছিল); লোডিং+আনলোডিং খরচ একটি কলামে মেশানো হয়েছে; পরিবহন ভাড়া এখন "প্রতি ট্রিপ" ভিত্তিতে + ট্রিপের হার (প্রতি কত দিনে কয় ট্রিপ); Transport_mode কলাম বাদ দেওয়া হয়েছে (মূল ফর্মে নেই)।
C39: Form_R: দোকান ভাড়া/বরফ/ধোয়া-পানি খরচ এখন প্রতি-দিন (BDT/day) ভিত্তিতে, আগে ভুলবশত মাসিক ছিল।
C40: Form_C: পেমেন্ট মেথড ও বাজার-পছন্দের কারণের অপশন তালিকা মূল ফর্মের সাথে হুবহু মেলানো হয়েছে (নগদ/বিকাশ/নগদ-অ্যাপ/বাকি; দাম/বৈচিত্র্য/নৈকট্য/বিশুদ্ধতা/পরিচিত দোকান)।
C41: Consumer_Purchases_Focal ও Price_Observations: বিক্রেতা/actor তালিকা মূল ফর্মের ভাষার সাথে মেলানো হয়েছে (খুচরা/ফেরিওয়ালা; Khuchra)।
C42: Progress_Dashboard ও QC_Check-এর সূত্র নতুন কলাম-অবস্থান অনুযায়ী আপডেট করা হয়েছে — কিছু হাতে ঠিক করার দরকার নেই।

Sheet Progress_Dashboard
B2: Field Progress Dashboard - target 120 respondents across 6 markets
B3: Counts update automatically from the Interview_Date column of each form sheet. Never type in this sheet.
B5: Market | C5: Aratdar (5) | D5: Bepari/Faria (5) | E5: Retailer (5) | F5: Consumer (5) | G5: Market total (20) | H5: Form M done
B6: M1 | C6: =COUNTIFS(Form_A_Aratdar!$C$5:$C$40,$B6,Form_A_Aratdar!$D$5:$D$40,"<>") | D6: =COUNTIFS(Form_B_Bepari_Faria!$C$5:$C$40,$B6,Form_B_Bepari_Faria!$D$5:$D$40,"<>") | E6: =COUNTIFS(Form_R_Khuchra!$C$5:$C$40,$B6,Form_R_Khuchra!$D$5:$D$40,"<>") | F6: =COUNTIFS(Form_C_Consumer!$C$5:$C$40,$B6,Form_C_Consumer!$D$5:$D$40,"<>") | G6: =SUM(C6:F6) | H6: =IF(COUNTIFS(Form_M_Market_Observation!$B$5:$B$10,$B6,Form_M_Market_Observation!$D$5:$D$10,"<>")>0,"Yes","No")
B7: M2 | C7: =COUNTIFS(Form_A_Aratdar!$C$5:$C$40,$B7,Form_A_Aratdar!$D$5:$D$40,"<>") | D7: =COUNTIFS(Form_B_Bepari_Faria!$C$5:$C$40,$B7,Form_B_Bepari_Faria!$D$5:$D$40,"<>") | E7: =COUNTIFS(Form_R_Khuchra!$C$5:$C$40,$B7,Form_R_Khuchra!$D$5:$D$40,"<>") | F7: =COUNTIFS(Form_C_Consumer!$C$5:$C$40,$B7,Form_C_Consumer!$D$5:$D$40,"<>") | G7: =SUM(C7:F7) | H7: =IF(COUNTIFS(Form_M_Market_Observation!$B$5:$B$10,$B7,Form_M_Market_Observation!$D$5:$D$10,"<>")>0,"Yes","No")
B8: M3 | C8: =COUNTIFS(Form_A_Aratdar!$C$5:$C$40,$B8,Form_A_Aratdar!$D$5:$D$40,"<>") | D8: =COUNTIFS(Form_B_Bepari_Faria!$C$5:$C$40,$B8,Form_B_Bepari_Faria!$D$5:$D$40,"<>") | E8: =COUNTIFS(Form_R_Khuchra!$C$5:$C$40,$B8,Form_R_Khuchra!$D$5:$D$40,"<>") | F8: =COUNTIFS(Form_C_Consumer!$C$5:$C$40,$B8,Form_C_Consumer!$D$5:$D$40,"<>") | G8: =SUM(C8:F8) | H8: =IF(COUNTIFS(Form_M_Market_Observation!$B$5:$B$10,$B8,Form_M_Market_Observation!$D$5:$D$10,"<>")>0,"Yes","No")
B9: M4 | C9: =COUNTIFS(Form_A_Aratdar!$C$5:$C$40,$B9,Form_A_Aratdar!$D$5:$D$40,"<>") | D9: =COUNTIFS(Form_B_Bepari_Faria!$C$5:$C$40,$B9,Form_B_Bepari_Faria!$D$5:$D$40,"<>") | E9: =COUNTIFS(Form_R_Khuchra!$C$5:$C$40,$B9,Form_R_Khuchra!$D$5:$D$40,"<>") | F9: =COUNTIFS(Form_C_Consumer!$C$5:$C$40,$B9,Form_C_Consumer!$D$5:$D$40,"<>") | G9: =SUM(C9:F9) | H9: =IF(COUNTIFS(Form_M_Market_Observation!$B$5:$B$10,$B9,Form_M_Market_Observation!$D$5:$D$10,"<>")>0,"Yes","No")
B10: M5 | C10: =COUNTIFS(Form_A_Aratdar!$C$5:$C$40,$B10,Form_A_Aratdar!$D$5:$D$40,"<>") | D10: =COUNTIFS(Form_B_Bepari_Faria!$C$5:$C$40,$B10,Form_B_Bepari_Faria!$D$5:$D$40,"<>") | E10: =COUNTIFS(Form_R_Khuchra!$C$5:$C$40,$B10,Form_R_Khuchra!$D$5:$D$40,"<>") | F10: =COUNTIFS(Form_C_Consumer!$C$5:$C$40,$B10,Form_C_Consumer!$D$5:$D$40,"<>") | G10: =SUM(C10:F10) | H10: =IF(COUNTIFS(Form_M_Market_Observation!$B$5:$B$10,$B10,Form_M_Market_Observation!$D$5:$D$10,"<>")>0,"Yes","No")
B11: M6 | C11: =COUNTIFS(Form_A_Aratdar!$C$5:$C$40,$B11,Form_A_Aratdar!$D$5:$D$40,"<>") | D11: =COUNTIFS(Form_B_Bepari_Faria!$C$5:$C$40,$B11,Form_B_Bepari_Faria!$D$5:$D$40,"<>") | E11: =COUNTIFS(Form_R_Khuchra!$C$5:$C$40,$B11,Form_R_Khuchra!$D$5:$D$40,"<>") | F11: =COUNTIFS(Form_C_Consumer!$C$5:$C$40,$B11,Form_C_Consumer!$D$5:$D$40,"<>") | G11: =SUM(C11:F11) | H11: =IF(COUNTIFS(Form_M_Market_Observation!$B$5:$B$10,$B11,Form_M_Market_Observation!$D$5:$D$10,"<>")>0,"Yes","No")
B12: TOTAL | C12: =SUM(C6:C11) | D12: =SUM(D6:D11) | E12: =SUM(E6:E11) | F12: =SUM(F6:F11) | G12: =SUM(G6:G11) | H12: =IF(G12=120,"TARGET MET","In progress")
B14: Dataset progress
B15: Interviews entered (of 120) | C15: =G12
B16: Target reached (%) | C16: =G12/120
B17: Price_Observations rows entered | C17: =COUNTIF(Price_Observations!$C$5:$C$504,"<>")
B18: of which Aratdar quotes | C18: =COUNTIF(Price_Observations!$E$5:$E$504,"Aratdar")
B19: of which Bepari/Faria quotes | C19: =COUNTIF(Price_Observations!$E$5:$E$504,"Bepari_Faria")
B20: of which Retailer quotes | C20: =COUNTIF(Price_Observations!$E$5:$E$504,"Khuchra")
B21: Consumer_Purchases_Focal rows entered | C21: =COUNTIF(Consumer_Purchases_Focal!$B$5:$B$354,"<>")
B22: Consumer_Other_Fish rows entered | C22: =COUNTIF(Consumer_Other_Fish!$B$5:$B$104,"<>")
B23: Tag_Price_Sheet rows entered (optional) | C23: =COUNTIF(Tag_Price_Sheet!$C$5:$C$324,"<>")
B24: Data_Collection_Log days used | C24: =COUNTIF(Data_Collection_Log!$B$5:$B$44,"<>")
B26: Quota per market: 5 aratdar + 5 bepari/faria + 5 khuchra retailers + 5 consumers (Methodology Table 3.3).

Sheet Data_Collection_Log
B2: Data Collection Log - one row per field visit
B4: Date | C4: Weekday | D4: Market | E4: Collector_name | F4: Session_start | G4: Session_end | H4: Ref_day_prices_used | I4: Traders_interviewed | J4: Consumers_interviewed | K4: Weather_notes | L4: Notes
B5: 46083 | C5: =IF($B5="","",TEXT($B5,"ddd")) | D5: M1 | E5: Field Team A | F5: 05:30 | G5: 09:00 | H5: No | I5: 4 | J5: 1 | K5: Light fog, calm sea | L5: Pilot day - Chattogram
B6: 46084 | C6: =IF($B6="","",TEXT($B6,"ddd")) | D6: M1 | E6: Field Team A | F6: 04:30 | G6: 09:00 | H6: No | I6: 15 | J6: 5 | K6: Fair, moderate NE wind | L6: Fishery Ghat landing - main round
B7: 46084 | C7: =IF($B7="","",TEXT($B7,"ddd")) | D7: M6 | E7: Field Team B | F7: 09:45 | G7: 13:30 | H7: No | I7: 15 | J7: 5 | K7: Sunny | L7: Patenga landing
B8: 46085 | C8: =IF($B8="","",TEXT($B8,"ddd")) | D8: M2 | E8: Field Team A | F8: 07:00 | G8: 11:30 | H8: No | I8: 15 | J8: 5 | K8: Sunny and humid | L8: Chawkbazar retail
B9: 46086 | C9: =IF($B9="","",TEXT($B9,"ddd")) | D9: M3 | E9: Field Team B | F9: 07:30 | G9: 12:00 | H9: No | I9: 15 | J9: 5 | K9: Overcast | L9: Kazir Dewri
B10: 46087 | C10: =IF($B10="","",TEXT($B10,"ddd")) | D10: M4 | E10: Field Team A | F10: 06:30 | G10: 10:30 | H10: Yes | I10: 15 | J10: 5 | K10: Hot, 33C | L10: Karnaphuli Complex
B11: 46088 | C11: =IF($B11="","",TEXT($B11,"ddd")) | D11: M5 | E11: Field Team B | F11: 07:00 | G11: 11:30 | H11: No | I11: 15 | J11: 5 | K11: Fair | L11: Bahaddarhat
C12: =IF($B12="","",TEXT($B12,"ddd"))
C13: =IF($B13="","",TEXT($B13,"ddd"))
C14: =IF($B14="","",TEXT($B14,"ddd"))
C15: =IF($B15="","",TEXT($B15,"ddd"))
C16: =IF($B16="","",TEXT($B16,"ddd"))
C17: =IF($B17="","",TEXT($B17,"ddd"))
C18: =IF($B18="","",TEXT($B18,"ddd"))
C19: =IF($B19="","",TEXT($B19,"ddd"))
C20: =IF($B20="","",TEXT($B20,"ddd"))
C21: =IF($B21="","",TEXT($B21,"ddd"))
C22: =IF($B22="","",TEXT($B22,"ddd"))
C23: =IF($B23="","",TEXT($B23,"ddd"))
... C44: =IF($B44="","",TEXT($B44,"ddd"))

Sheet Unit_Converter
B2: Maund - Kilogram Converter
B4: 1 maund = 37.32 kilograms (official conversion used throughout this study)
B6: Maunds -> kilograms
B7: Type maund value here | C7: 1
B8: Result - kilograms | C8: =IF(ISNUMBER($C$7),$C$7*37.32,"")
B10: Kilograms -> maunds
B11: Type kg value here | C11: 37.32
B12: Result - maunds | C12: =IF(ISNUMBER($C$11),ROUND($C$11/37.32,4),"")
B14: Reminder - price flags
B15: K | C15: Species not handled by the respondent today.
B16: D | C16: Price declined - keep the row, the flag itself is information.
B17: 0 / '-' | C17: True zero / not applicable. Empty cells are not allowed in species grids.
B18: Conversion | C18: Blue BDT_per_kg columns convert maund quotes automatically - never type over them.

Sheet Codebook_Species
B2: Species Codebook (Methodology Table 3.4)
B4: Code | C4: Local_name | D4: English_common_name | E4: Scientific_name | F4: Price_tier
B5: S01 | C5: Ilish | D5: Hilsa shad | E5: Tenualosa ilisha | F5: High
B6: S02 | C6: Rupchanda | D6: Silver pomfret | E6: Pampus argenteus | F6: High
B7: S03 | C7: Lakkha | D7: Indian salmon (four-finger threadfin) | E7: Eleutheronema tetradactylum | F7: High
B8: S04 | C8: Koral/Kurl | D8: Asian sea bass | E8: Lates calcarifer | F8: High
B9: S05 | C9: Surma | D9: Indian mackerel | E9: Rastrelliger kanagurta | F9: Medium
B10: S06 | C10: Churi | D10: Largehead ribbonfish | E10: Trichiurus lepturus | F10: Medium
B11: S07 | C11: Poa | D11: Pama croaker | E11: Otolithoides pama | F11: Medium
B12: S08 | C12: Kankoita | D12: Thorny/Indian anchovy | E12: Stolephorus indicus | F12: Low-volume
B13: S09 | C13: Loitta | D13: Bombay duck | E13: Harpadon nehereus | F13: Low
B14: S10 | C14: Harina | D14: Chacunda gizzard shad | E14: Anodontostoma chacunda | F14: Low

Sheet Codebook_Markets
B2: Market Codebook (Methodology Table 3.1)
B4: Code | C4: Market_name | D4: Channel_position | E4: Primary_analytical_contribution
B5: M1 | C5: Fishery Ghat | D5: Landing-linked wholesale-cum-retail | E5: First-sale (producer-side) price observations
B6: M2 | C6: Chawkbazar | D6: Retail | E6: Retail prices and trade volume quotes
B7: M3 | C7: Kazir Dewri | D7: Retail | E7: Retail prices and vendor practices
B8: M4 | C8: Karnaphuli Complex | D8: Retail | E8: Retail prices; comparability with the 2019 baseline
B9: M5 | C9: Bahaddarhat | D9: Retail | E9: Newer-generation retail turnover
B10: M6 | C10: Patenga | D10: Landing-linked retail | E10: Coast-side buy prices supporting producer-share estimation

Sheet Form_A_Aratdar
B2: Form A - Aratdar Questionnaire (one respondent per row)
B4: Respondent_ID | C4: Market | D4: Interview_Date | E4: Age_years | F4: Education | G4: Years_in_business | H4: Daily_capacity_raw | I4: Daily_capacity_unit | J4: Daily_capacity_kg | K4: Family_members | L4: Rent_pay_or_receive | M4: Rent_amount_BDT | N4: Rent_frequency | O4: Commission_basis | P4: Commission_rate | Q4: Electricity_bill_BDT | R4: Electricity_frequency | S4: Workers_count | T4: Worker_daily_wage_BDT | U4: Equipment_Cooler_Maintenance_BDT | V4: Equipment_Cooler_Maintenance_frequency | W4: Other_cost_description | X4: Other_cost_BDT | Y4: Payment_cash_pct | Z4: Payment_MFS_pct | AA4: Payment_credit_pct | AB4: MFS_transaction_frequency | AC4: Problem_1 | AD4: Problem_2 | AE4: Problem_3 | AF4: Pair_ID | AG4: Notes
B5: M1-A-01 | C5: M1 | D5: 46084 | E5: 50 | F5: Secondary | G5: 12 | H5: 18 | I5: Maund | J5: 671.76 | K5: 4 | L5: Pay | M5: 30000 | N5: Monthly | O5: Percent | P5: 3 | Q5: 11400 | R5: Monthly | S5: 8 | T5: 600 | U5: 5000 | V5: Monthly | W5: Auction hall cleaning fee | X5: 1100 | Y5: 67 | Z5: 22 | AA5: 11 | AB5: Occasional | AC5: Low landings in lean season | AD5: Unsold fish spoilage loss | AE5: Supply syndicate control | AF5: PAIR-M1-02
B6: M1-A-02 | C6: M1 | D6: 46084 | E6: 32 | F6: Secondary | G6: 16 | H6: 19 | I6: Maund | J6: 709.08 | K6: 3 | L6: Pay | M6: 420000 | N6: Yearly | O6: Kg | P6: 1 | Q6: 8700 | R6: Monthly | S6: 7 | T6: 550 | U6: 7500 | V6: Monthly | W6: Auction hall cleaning fee | X6: 1150 | Y6: 65 | Z6: 10 | AA6: 25 | AB6: Regular | AC6: Rising cost of ice and salt | AD6: Delayed credit recovery | AE6: Competition from frozen imported fish
B7: M1-A-03 | C7: M1 | D7: 46084 | E7: 55 | F7: Secondary | G7: 32 | H7: 14 | I7: Maund | J7: 522.48 | K7: 4 | L7: Pay | M7: 420000 | N7: Yearly | O7: Lot | P7: 1000 | Q7: 12700 | R7: Monthly | S7: 3 | T7: 800 | U7: 12000 | V7: Yearly | W7: Weighing scale repair | X7: 950 | Y7: 80 | Z7: 8 | AA7: 12 | AB7: Regular | AC7: Competition from frozen imported fish | AD7: Day-to-day price volatility | AE7: Transport cost increase
B8: M1-A-04 | C8: M1 | D8: 46084 | E8: 39 | F8: Secondary | G8: 17 | H8: 11 | I8: Maund | J8: 410.52 | K8: 5 | L8: Pay | M8: 240000 | N8: Yearly | O8: Percent | P8: 2 | Q8: 5800 | R8: Monthly | S8: 5 | T8: 700 | U8: 6500 | V8: Yearly | W8: Auction hall cleaning fee | X8: 450 | Y8: 69 | Z8: 20 | AA8: 11 | AB8: Occasional | AC8: Delayed credit recovery | AD8: Supply syndicate control | AE8: Low landings in lean season
B9: M1-A-05 | C9: M1 | D9: 46084 | E9: 57 | F9: Primary | G9: 31 | H9: 29 | I9: Maund | J9: 1082.28 | K9: 9 | L9: Pay | M9: 380000 | N9: Yearly | O9: Percent | P9: 3 | Q9: 12000 | R9: Monthly | S9: 8 | T9: 500 | U9: 9500 | V9: Yearly | W9: Market committee toll | X9: 2000 | Y9: 65 | Z9: 13 | AA9: 22 | AB9: Occasional | AC9: Day-to-day price volatility | AD9: Competition from frozen imported fish | AE9: Rising cost of ice and salt | AF9: PAIR-M1-01
B10: M1-A-06 | C10: M1
B11: M2-A-01 | C11: M2 | D11: 46085 | E11: 29 | F11: Secondary | G11: 13 | H11: 26 | I11: Maund | J11: 970.32 | K11: 3 | L11: Receive | M11: 2000 | N11: Monthly | O11: Percent | P11: 3.5 | Q11: 11100 | R11: Monthly | S11: 6 | T11: 800 | U11: 9000 | V11: Yearly | W11: Weighing scale repair | X11: 500 | Y11: 77 | Z11: 16 | AA11: 7 | AB11: Regular | AC11: Low landings in lean season | AD11: High ice price | AE11: Irregular electricity and load-shedding | AF11: PAIR-M2-02
B12: M2-A-02 | C12: M2 | D12: 46085 | E12: 52 | F12: Illiterate | G12: 20 | H12: 32 | I12: Maund | J12: 1194.24 | K12: 8 | L12: Receive | M12: 2500 | N12: Monthly | O12: Kg | P12: 3 | Q12: 4400 | R12: Monthly | S12: 6 | T12: 650 | U12: 11000 | V12: Yearly | W12: Ice block purchase | X12: 1800 | Y12: 73 | Z12: 7 | AA12: 20 | AB12: Regular | AC12: Competition from frozen imported fish | AD12: Low landings in lean season | AE12: Rising toll and lease burden
B13: M2-A-03 | C13: M2 | D13: 46085 | E13: 34 | F13: Primary | G13: 12 | H13: 10 | I13: Maund | J13: 373.2 | K13: 7 | L13: Pay | M13: 80000 | N13: Yearly | O13: Lot | P13: 500 | Q13: 5300 | R13: Monthly | S13: 6 | T13: 500 | U13: 11000 | V13: Yearly | W13: Ice block purchase | X13: 1300 | Y13: 66 | Z13: 16 | AA13: 18 | AB13: Regular | AC13: Waterlogging during monsoon | AD13: Rising toll and lease burden | AE13: Rising cost of ice and salt
B14: M2-A-04 | C14: M2 | D14: 46085 | E14: 59 | F14: Higher_Secondary | G14: 34 | H14: 21 | I14: Maund | J14: 783.72 | K14: 9 | L14: Pay | M14: 150000 | N14: Yearly | O14: Kg | P14: 3 | Q14: 5000 | R14: Monthly | S14: 3 | T14: 800 | U14: 9000 | V14: Monthly | W14: Weighing scale repair | X14: 1350 | Y14: 61 | Z14: 24 | AA14: 15 | AB14: Never | AC14: Unsold fish spoilage loss | AD14: Waterlogging during monsoon | AE14: High ice price | AF14: PAIR-M2-01
B15: M2-A-05 | C15: M2 | D15: 46085 | E15: 31 | F15: Primary | G15: 11 | H15: 8 | I15: Maund | J15: 298.56 | K15: 5 | L15: Pay | M15: 21000 | N15: Monthly | O15: Percent | P15: 2.5 | Q15: 3100 | R15: Monthly | S15: 6 | T15: 650 | U15: 7500 | V15: Monthly | W15: Union levy | X15: 2300 | Y15: 80 | Z15: 15 | AA15: 5 | AB15: Regular | AC15: Day-to-day price volatility | AD15: Competition from frozen imported fish | AE15: Supply syndicate control | AF15: PAIR-M2-03
B16: M2-A-06 | C16: M2
B17: M3-A-01 | C17: M3 | D17: 46086 | E17: 51 | F17: Secondary | G17: 18 | H17: 21 | I17: Maund | J17: 783.72 | K17: 3 | L17: Pay | M17: 175000 | N17: Yearly | O17: Percent | P17: 2.5 | Q17: 9700 | R17: Monthly | S17: 9 | T17: 600 | U17: 7500 | V17: Monthly | W17: Union levy | X17: 1100 | Y17: 77 | Z17: 14 | AA17: 9 | AB17: Occasional | AC17: High ice price | AD17: Low landings in lean season | AE17: Waterlogging during monsoon
B18: M3-A-02 | C18: M3 | D18: 46086 | E18: 41 | F18: Secondary | G18: 25 | H18: 31 | I18: Maund | J18: 1156.92 | K18: 4 | L18: Pay | M18: 9000 | N18: Monthly | O18: Percent | P18: 2 | Q18: 7600 | R18: Yearly | S18: 4 | T18: 800 | U18: 8500 | V18: Yearly | W18: Union levy | X18: 1350 | Y18: 76 | Z18: 5 | AA18: 19 | AB18: Regular | AC18: Competition from frozen imported fish | AD18: Waterlogging during monsoon | AE18: Transport cost increase | AF18: PAIR-M3-01
B19: M3-A-03 | C19: M3 | D19: 46086 | E19: 58 | F19: Primary | G19: 30 | H19: 29 | I19: Maund | J19: 1082.28 | K19: 7 | L19: Pay | M19: 165000 | N19: Yearly | O19: Kg | P19: 1.5 | Q19: 3200 | R19: Monthly | S19: 6 | T19: 550 | U19: 6500 | V19: Yearly | W19: Auction hall cleaning fee | X19: 950 | Y19: 68 | Z19: 16 | AA19: 16 | AB19: Occasional | AC19: Rising cost of ice and salt | AD19: Low landings in lean season | AE19: Waterlogging during monsoon
B20: M3-A-04 | C20: M3 | D20: 46086 | E20: 48 | F20: Primary | G20: 8 | H20: 20 | I20: Maund | J20: 746.4 | K20: 3 | L20: Pay | M20: 75000 | N20: Yearly | O20: Percent | P20: 2 | Q20: 7300 | R20: Monthly | S20: 6 | T20: 550 | U20: 4000 | V20: Yearly | W20: Ice block purchase | X20: 1950 | Y20: 78 | Z20: 5 | AA20: 17 | AB20: Occasional | AC20: Rising cost of ice and salt | AD20: Day-to-day price volatility | AE20: Delayed credit recovery
B21: M3-A-05 | C21: M3 | D21: 46086 | E21: 46 | F21: Secondary | G21: 30 | H21: 26 | I21: Maund | J21: 970.32 | K21: 5 | L21: Receive | M21: 3500 | N21: Monthly | O21: Percent | P21: 2 | Q21: 11700 | R21: Monthly | S21: 3 | T21: 650 | U21: 2500 | V21: Yearly | W21: Weighing scale repair | X21: 800 | Y21: 73 | Z21: 7 | AA21: 20 | AB21: Occasional | AC21: High ice price | AD21: Low landings in lean season | AE21: Irregular electricity and load-shedding | AF21: PAIR-M3-02
B22: M3-A-06 | C22: M3
B23: M4-A-01 | C23: M4 | D23: 46087 | E23: 52 | F23: Primary | G23: 23 | H23: 28 | I23: Maund | J23: 1044.96 | K23: 8 | L23: Pay | M23: 17000 | N23: Monthly | O23: Percent | P23: 3.5 | Q23: 7100 | R23: Monthly | S23: 7 | T23: 550 | U23: 4000 | V23: Yearly | W23: Weighing scale repair | X23: 550 | Y23: 62 | Z23: 6 | AA23: 32 | AB23: Never | AC23: Unsold fish spoilage loss | AD23: Waterlogging during monsoon | AE23: Low landings in lean season | AF23: PAIR-M4-01
B24: M4-A-02 | C24: M4 | D24: 46087 | E24: 57 | F24: Secondary | G24: 24 | H24: 32 | I24: Maund | J24: 1194.24 | K24: 8 | L24: Pay | M24: 100000 | N24: Yearly | O24: Percent | P24: 4 | Q24: 11800 | R24: Monthly | S24: 5 | T24: 750 | U24: 9500 | V24: Monthly | W24: Auction hall cleaning fee | X24: 350 | Y24: 66 | Z24: 20 | AA24: 14 | AB24: Regular | AC24: Competition from frozen imported fish | AD24: Unsold fish spoilage loss | AE24: Delayed credit recovery | AF24: PAIR-M4-03
B25: M4-A-03 | C25: M4 | D25: 46087 | E25: 37 | F25: Secondary | G25: 21 | H25: 9 | I25: Maund | J25: 335.88 | K25: 8 | L25: Pay | M25: 110000 | N25: Yearly | O25: Percent | P25: 3.5 | Q25: 7200 | R25: Monthly | S25: 2 | T25: 650 | U25: 10000 | V25: Monthly | W25: Weighing scale repair | X25: 650 | Y25: 76 | Z25: 18 | AA25: 6 | AB25: Regular | AC25: Rising toll and lease burden | AD25: Rising cost of ice and salt | AE25: Unsold fish spoilage loss | AF25: PAIR-M4-02
B26: M4-A-04 | C26: M4 | D26: 46087 | E26: 40 | F26: Primary | G26: 5 | H26: 26 | I26: Maund | J26: 970.32 | K26: 7 | L26: Pay | M26: 175000 | N26: Yearly | O26: Percent | P26: 4 | Q26: 6500 | R26: Monthly | S26: 8 | T26: 650 | U26: 3500 | V26: Yearly | W26: Union levy | X26: 1300 | Y26: 67 | Z26: 9 | AA26: 24 | AB26: Occasional | AC26: Rising cost of ice and salt | AD26: Delayed credit recovery | AE26: Transport cost increase
B27: M4-A-05 | C27: M4 | D27: 46087 | E27: 62 | F27: Higher_Secondary | G27: 27 | H27: 24 | I27: Maund | J27: 895.68 | K27: 5 | L27: Pay | M27: 120000 | N27: Yearly | O27: Lot | P27: 2000 | Q27: 4400 | R27: Monthly | S27: 3 | T27: 700 | U27: 8000 | V27: Yearly | W27: Weighing scale repair | X27: 800 | Y27: 67 | Z27: 18 | AA27: 15 | AB27: Regular | AC27: Waterlogging during monsoon | AD27: Irregular electricity and load-shedding | AE27: Competition from frozen imported fish
B28: M4-A-06 | C28: M4
B29: M5-A-01 | C29: M5 | D29: 46088 | E29: 58 | F29: Illiterate | G29: 20 | H29: 29 | I29: Maund | J29: 1082.28 | K29: 4 | L29: Pay | M29: 190000 | N29: Yearly | O29: Percent | P29: 2.5 | Q29: 2900 | R29: Monthly | S29: 2 | T29: 700 | U29: 10500 | V29: Yearly | W29: Market committee toll | X29: 1050 | Y29: 56 | Z29: 25 | AA29: 19 | AB29: Occasional | AC29: Day-to-day price volatility | AD29: Unsold fish spoilage loss | AE29: Waterlogging during monsoon | AF29: PAIR-M5-03
B30: M5-A-02 | C30: M5 | D30: 46088 | E30: 44 | F30: Primary | G30: 28 | H30: 9 | I30: Maund | J30: 335.88 | K30: 7 | L30: Pay | M30: 10000 | N30: Monthly | O30: Lot | P30: 2000 | Q30: 8200 | R30: Monthly | S30: 3 | T30: 650 | U30: 8500 | V30: Yearly | W30: Weighing scale repair | X30: 1250 | Y30: 71 | Z30: 20 | AA30: 9 | AB30: Occasional | AC30: Supply syndicate control | AD30: Competition from frozen imported fish | AE30: Day-to-day price volatility | AF30: PAIR-M5-02
B31: M5-A-03 | C31: M5 | D31: 46088 | E31: 38 | F31: Primary | G31: 22 | H31: 12 | I31: Maund | J31: 447.84 | K31: 9 | L31: Receive | M31: 4000 | N31: Monthly | O31: Percent | P31: 3 | Q31: 10500 | R31: Monthly | S31: 3 | T31: 700 | U31: 2000 | V31: Yearly | W31: Ice block purchase | X31: 2250 | Y31: 73 | Z31: 15 | AA31: 12 | AB31: Regular | AC31: Delayed credit recovery | AD31: High ice price | AE31: Unsold fish spoilage loss | AF31: PAIR-M5-01
B32: M5-A-04 | C32: M5 | D32: 46088 | E32: 40 | F32: Secondary | G32: 24 | H32: 33 | I32: Maund | J32: 1231.56 | K32: 8 | L32: Receive | M32: 2000 | N32: Monthly | O32: Percent | P32: 2.5 | Q32: 13100 | R32: Monthly | S32: 3 | T32: 800 | U32: 3000 | V32: Yearly | W32: Auction hall cleaning fee | X32: 650 | Y32: 64 | Z32: 20 | AA32: 16 | AB32: Occasional | AC32: Waterlogging during monsoon | AD32: Competition from frozen imported fish | AE32: Irregular electricity and load-shedding
B33: M5-A-05 | C33: M5 | D33: 46088 | E33: 50 | F33: Primary | G33: 10 | H33: 11 | I33: Maund | J33: 410.52 | K33: 5 | L33: Pay | M33: 130000 | N33: Yearly | O33: Percent | P33: 5 | Q33: 2700 | R33: Monthly | S33: 9 | T33: 700 | U33: 8500 | V33: Monthly | W33: Weighing scale repair | X33: 650 | Y33: 69 | Z33: 18 | AA33: 13 | AB33: Regular | AC33: Transport cost increase | AD33: Supply syndicate control | AE33: High ice price
B34: M5-A-06 | C34: M5
B35: M6-A-01 | C35: M6 | D35: 46084 | E35: 41 | F35: Secondary | G35: 22 | H35: 33 | I35: Maund | J35: 1231.56 | K35: 3 | L35: Pay | M35: 175000 | N35: Yearly | O35: Lot | P35: 2500 | Q35: 6000 | R35: Monthly | S35: 3 | T35: 800 | U35: 1500 | V35: Yearly | W35: Union levy | X35: 1700 | Y35: 80 | Z35: 12 | AA35: 8 | AB35: Occasional | AC35: Unsold fish spoilage loss | AD35: Delayed credit recovery | AE35: High ice price
B36: M6-A-02 | C36: M6 | D36: 46084 | E36: 59 | F36: Secondary | G36: 40 | H36: 26 | I36: Maund | J36: 970.32 | K36: 8 | L36: Pay | M36: 140000 | N36: Yearly | O36: Lot | P36: 500 | Q36: 9700 | R36: Monthly | S36: 7 | T36: 750 | U36: 8000 | V36: Monthly | W36: Market committee toll | X36: 2500 | Y36: 79 | Z36: 14 | AA36: 7 | AB36: Never | AC36: High ice price | AD36: Supply syndicate control | AE36: Rising toll and lease burden | AF36: PAIR-M6-01
B37: M6-A-03 | C37: M6 | D37: 46084 | E37: 46 | F37: Illiterate | G37: 5 | H37: 12 | I37: Maund | J37: 447.84 | K37: 3 | L37: Pay | M37: 19000 | N37: Monthly | O37: Percent | P37: 3.5 | Q37: 9900 | R37: Monthly | S37: 8 | T37: 750 | U37: 4000 | V37: Monthly | W37: Union levy | X37: 600 | Y37: 55 | Z37: 6 | AA37: 39 | AB37: Regular | AC37: Waterlogging during monsoon | AD37: Rising cost of ice and salt | AE37: Unsold fish spoilage loss
B38: M6-A-04 | C38: M6 | D38: 46084 | E38: 57 | F38: Primary | G38: 30 | H38: 34 | I38: Maund | J38: 1268.88 | K38: 7 | L38: Pay | M38: 125000 | N38: Yearly | O38: Percent | P38: 2.5 | Q38: 12200 | R38: Monthly | S38: 6 | T38: 650 | U38: 6000 | V38: Yearly | W38: Auction hall cleaning fee | X38: 800 | Y38: 66 | Z38: 12 | AA38: 22 | AB38: Regular | AC38: Delayed credit recovery | AD38: Day-to-day price volatility | AE38: Low landings in lean season
B39: M6-A-05 | C39: M6 | D39: 46084 | E39: 50 | F39: Illiterate | G39: 9 | H39: 11 | I39: Maund | J39: 410.52 | K39: 8 | L39: Receive | M39: 3500 | N39: Monthly | O39: Percent | P39: 2 | Q39: 6600 | R39: Monthly | S39: 9 | T39: 700 | U39: 6500 | V39: Yearly | W39: Ice block purchase | X39: 2700 | Y39: 63 | Z39: 14 | AA39: 23 | AB39: Never | AC39: Rising toll and lease burden | AD39: High ice price | AE39: Competition from frozen imported fish | AF39: PAIR-M6-02
B40: M6-A-06 | C40: M6

Sheet Form_B_Bepari_Faria
B2: Form B - Bepari/Faria Questionnaire (one respondent per row)
B4: Respondent_ID | C4: Market | D4: Interview_Date | E4: Actor_subtype | F4: Business_pattern | G4: Age_years | H4: Education | I4: Years_in_business | J4: Daily_capacity_raw | K4: Daily_capacity_unit | L4: Daily_capacity_kg | M4: Family_members | N4: Source_location | O4: Supplier_category | P4: Transport_fare_per_trip_BDT | Q4: Trip_frequency_days | R4: Trips_per_period | S4: Loading_Unloading_cost_per_trip_BDT | T4: Ice_usage_kg_per_day | U4: Ice_cost_BDT_per_day | V4: Commission_to_aratdar_value | W4: Commission_unit | X4: Transit_damage_pct | Y4: Payment_cash_pct | Z4: Payment_MFS_pct | AA4: Payment_credit_pct | AB4: MFS_transaction_frequency | AC4: Credit_sales_share | AD4: Problem_1 | AE4: Problem_2 | AF4: Problem_3 | AG4: Pair_ID | AH4: Notes
B5: M1-B-01 | C5: M1 | D5: 46084 | E5: Bepari | F5: Seasonal | G5: 43 | H5: Primary | I5: 27 | J5: 5 | K5: Maund | L5: 186.6 | M5: 7 | N5: Fishery Ghat landing | O5: Faria | P5: 1750 | Q5: 2 | R5: 1 | S5: 250 | T5: 44 | U5: 170 | V5: 3 | W5: Percent_of_lot | X5: 4 | Y5: 55 | Z5: 15 | AA5: 30 | AB5: Regular | AC5: Some | AD5: High ice price | AE5: Low landings in lean season | AF5: Rising toll and lease burden
B6: M1-B-02 | C6: M1 | D6: 46084 | E6: Bepari | F6: Seasonal | G6: 25 | H6: Secondary | I6: 9 | J6: 7 | K6: Maund | L6: 261.24 | M6: 6 | N6: Karnaphuli river ghat | O6: Other | P6: 450 | Q6: 2 | R6: 1 | S6: 500 | T6: 35 | U6: 130 | V6: 4 | W6: Percent_of_lot | X6: 7 | Y6: 55 | Z6: 30 | AA6: 15 | AB6: Regular | AC6: None | AD6: Day-to-day price volatility | AE6: Rising cost of ice and salt | AF6: Rising toll and lease burden
B7: M1-B-03 | C7: M1 | D7: 46084 | E7: Bepari | F7: Seasonal | G7: 27 | H7: Illiterate | I7: 11 | J7: 5 | K7: Maund | L7: 186.6 | M7: 7 | N7: Fishery Ghat landing | O7: Aratdar | P7: 900 | Q7: 3 | R7: 1 | S7: 150 | T7: 109 | U7: 300 | V7: 3 | W7: Percent_of_lot | X7: 5 | Y7: 67 | Z7: 27 | AA7: 6 | AB7: Never | AC7: Some | AD7: Rising cost of ice and salt | AE7: Low landings in lean season | AF7: Waterlogging during monsoon
B8: M1-B-04 | C8: M1 | D8: 46084 | E8: Bepari | F8: Seasonal | G8: 51 | H8: Secondary | I8: 5 | J8: 4 | K8: Maund | L8: 149.28 | M8: 7 | N8: Karnaphuli river ghat | O8: Aratdar | P8: 500 | Q8: 2 | R8: 3 | S8: 100 | T8: 32 | U8: 80 | V8: 4 | W8: Percent_of_lot | X8: 8 | Y8: 79 | Z8: 10 | AA8: 11 | AB8: Occasional | AC8: None | AD8: Rising toll and lease burden | AE8: Day-to-day price volatility | AF8: Waterlogging during monsoon
B9: M1-B-05 | C9: M1 | D9: 46084 | E9: Bepari | F9: Year_round | G9: 40 | H9: Secondary | I9: 18 | J9: 4 | K9: Maund | L9: 149.28 | M9: 3 | N9: Karnaphuli river ghat | O9: Aratdar | P9: 2650 | Q9: 3 | R9: 1 | S9: 100 | T9: 99 | U9: 390 | V9: 800 | W9: BDT_per_lot | X9: 8 | Y9: 54 | Z9: 28 | AA9: 18 | AB9: Occasional | AC9: Some | AD9: Supply syndicate control | AE9: High ice price | AF9: Low landings in lean season
B10: M1-B-06 | C10: M1
B11: M2-B-01 | C11: M2 | D11: 46085 | E11: Bepari | F11: Year_round | G11: 45 | H11: Primary | I11: 12 | J11: 4 | K11: Maund | L11: 149.28 | M11: 4 | N11: Kuakata | O11: Fisherman | P11: 1650 | Q11: 1 | R11: 2 | S11: 250 | T11: 65 | U11: 180 | V11: 4 | W11: Percent_of_lot | X11: 6 | Y11: 62 | Z11: 15 | AA11: 23 | AB11: Regular | AC11: Some | AD11: Irregular electricity and load-shedding | AE11: Supply syndicate control | AF11: Unsold fish spoilage loss
B12: M2-B-02 | C12: M2 | D12: 46085 | E12: Bepari | F12: Year_round | G12: 46 | H12: Secondary | I12: 25 | J12: 6 | K12: Maund | L12: 223.92 | M12: 8 | N12: Teknaf | O12: Fisherman | P12: 2400 | Q12: 3 | R12: 3 | S12: 150 | T12: 110 | U12: 310 | V12: 3 | W12: Percent_of_lot | X12: 8 | Y12: 60 | Z12: 7 | AA12: 33 | AB12: Regular | AC12: Some | AD12: Delayed credit recovery | AE12: Rising toll and lease burden | AF12: Rising cost of ice and salt
B13: M2-B-03 | C13: M2 | D13: 46085 | E13: Bepari | F13: Year_round | G13: 51 | H13: Secondary | I13: 9 | J13: 9 | K13: Maund | L13: 335.88 | M13: 4 | N13: Karnaphuli river ghat | O13: Fisherman | P13: 3250 | Q13: 2 | R13: 2 | S13: 100 | T13: 88 | U13: 220 | V13: 4 | W13: Percent_of_lot | X13: 3 | Y13: 56 | Z13: 23 | AA13: 21 | AB13: Occasional | AC13: None | AD13: Supply syndicate control | AE13: Delayed credit recovery | AF13: Irregular electricity and load-shedding
B14: M2-B-04 | C14: M2 | D14: 46085 | E14: Bepari | F14: Year_round | G14: 27 | H14: Secondary | I14: 11 | J14: 8 | K14: Maund | L14: 298.56 | M14: 2 | N14: Kuakata | O14: Aratdar | P14: 2300 | Q14: 2 | R14: 2 | S14: 450 | T14: 68 | U14: 260 | V14: 3.5 | W14: Percent_of_lot | X14: 5 | Y14: 68 | Z14: 8 | AA14: 24 | AB14: Occasional | AC14: None | AD14: Day-to-day price volatility | AE14: Transport cost increase | AF14: Waterlogging during monsoon
B15: M2-B-05 | C15: M2 | D15: 46085 | E15: Bepari | F15: Year_round | G15: 58 | H15: Primary | I15: 5 | J15: 8 | K15: Maund | L15: 298.56 | M15: 4 | N15: Fishery Ghat landing | O15: Fisherman | P15: 2750 | Q15: 3 | R15: 1 | S15: 100 | T15: 57 | U15: 190 | V15: 2 | W15: Percent_of_lot | X15: 4 | Y15: 72 | Z15: 18 | AA15: 10 | AB15: Never | AC15: Some | AD15: Transport cost increase | AE15: Irregular electricity and load-shedding | AF15: Day-to-day price volatility
B16: M2-B-06 | C16: M2
B17: M3-B-01 | C17: M3 | D17: 46086 | E17: Bepari | F17: Year_round | G17: 34 | H17: Primary | I17: 18 | J17: 4 | K17: Maund | L17: 149.28 | M17: 2 | N17: Moheshkhali | O17: Faria | P17: 3200 | Q17: 3 | R17: 1 | S17: 100 | T17: 66 | U17: 220 | V17: 4 | W17: Percent_of_lot | X17: 5 | Y17: 54 | Z17: 21 | AA17: 25 | AB17: Occasional | AC17: Some | AD17: Low landings in lean season | AE17: Rising cost of ice and salt | AF17: Irregular electricity and load-shedding
B18: M3-B-02 | C18: M3 | D18: 46086 | E18: Faria | F18: Seasonal | G18: 43 | H18: Secondary | I18: 27 | J18: 3.9 | K18: Maund | L18: 145.55 | M18: 5 | N18: Kutubdia | O18: Fisherman | P18: 800 | Q18: 1 | R18: 3 | S18: 150 | T18: 64 | U18: 250 | V18: 1500 | W18: BDT_per_lot | X18: 2 | Y18: 77 | Z18: 10 | AA18: 13 | AB18: Occasional | AC18: Some | AD18: Transport cost increase | AE18: Rising cost of ice and salt | AF18: Low landings in lean season
B19: M3-B-03 | C19: M3 | D19: 46086 | E19: Bepari | F19: Seasonal | G19: 29 | H19: Secondary | I19: 13 | J19: 5 | K19: Maund | L19: 186.6 | M19: 3 | N19: Teknaf | O19: Fisherman | P19: 1750 | Q19: 1 | R19: 2 | S19: 450 | T19: 79 | U19: 220 | V19: 2 | W19: Percent_of_lot | X19: 2 | Y19: 76 | Z19: 15 | AA19: 9 | AB19: Regular | AC19: Some | AD19: Competition from frozen imported fish | AE19: High ice price | AF19: Delayed credit recovery
B20: M3-B-04 | C20: M3 | D20: 46086 | E20: Bepari | F20: Year_round | G20: 41 | H20: Primary | I20: 25 | J20: 4 | K20: Maund | L20: 149.28 | M20: 6 | N20: Bhola charter landing | O20: Faria | P20: 1950 | Q20: 3 | R20: 3 | S20: 500 | T20: 120 | U20: 470 | V20: 2.5 | W20: Percent_of_lot | X20: 7 | Y20: 79 | Z20: 5 | AA20: 16 | AB20: Regular | AC20: Some | AD20: Waterlogging during monsoon | AE20: Transport cost increase | AF20: Rising cost of ice and salt
B21: M3-B-05 | C21: M3 | D21: 46086 | E21: Bepari | F21: Year_round | G21: 30 | H21: Higher_Secondary | I21: 14 | J21: 4 | K21: Maund | L21: 149.28 | M21: 3 | N21: Teknaf | O21: Fisherman | P21: 3500 | Q21: 1 | R21: 2 | S21: 200 | T21: 38 | U21: 140 | V21: 3.5 | W21: Percent_of_lot | X21: 4 | Y21: 54 | Z21: 23 | AA21: 23 | AB21: Never | AC21: None | AD21: Rising cost of ice and salt | AE21: Day-to-day price volatility | AF21: Low landings in lean season
B22: M3-B-06 | C22: M3
B23: M4-B-01 | C23: M4 | D23: 46087 | E23: Bepari | F23: Year_round | G23: 54 | H23: Illiterate | I23: 33 | J23: 7 | K23: Maund | L23: 261.24 | M23: 4 | N23: Bhola charter landing | O23: Aratdar | P23: 800 | Q23: 1 | R23: 1 | S23: 500 | T23: 93 | U23: 260 | V23: 2 | W23: Percent_of_lot | X23: 7 | Y23: 51 | Z23: 16 | AA23: 33 | AB23: Occasional | AC23: Some | AD23: Irregular electricity and load-shedding | AE23: Day-to-day price volatility | AF23: High ice price
B24: M4-B-02 | C24: M4 | D24: 46087 | E24: Faria | F24: Year_round | G24: 50 | H24: Primary | I24: 17 | J24: 3.2 | K24: Maund | L24: 119.42 | M24: 8 | N24: Bhola charter landing | O24: Aratdar | P24: 3050 | Q24: 1 | R24: 3 | S24: 350 | T24: 74 | U24: 190 | V24: 2 | W24: Percent_of_lot | X24: 3 | Y24: 62 | Z24: 29 | AA24: 9 | AB24: Occasional | AC24: None | AD24: Rising toll and lease burden | AE24: Delayed credit recovery | AF24: Day-to-day price volatility
B25: M4-B-03 | C25: M4 | D25: 46087 | E25: Faria | F25: Seasonal | G25: 29 | H25: Primary | I25: 13 | J25: 3.6 | K25: Maund | L25: 134.35 | M25: 2 | N25: Bhola charter landing | O25: Aratdar | P25: 2600 | Q25: 1 | R25: 3 | S25: 450 | T25: 101 | U25: 400 | V25: 800 | W25: BDT_per_lot | X25: 6 | Y25: 70 | Z25: 10 | AA25: 20 | AB25: Occasional | AC25: Some | AD25: Rising cost of ice and salt | AE25: Waterlogging during monsoon | AF25: Rising toll and lease burden
B26: M4-B-04 | C26: M4 | D26: 46087 | E26: Bepari | F26: Year_round | G26: 44 | H26: Higher_Secondary | I26: 18 | J26: 9 | K26: Maund | L26: 335.88 | M26: 3 | N26: Moheshkhali | O26: Fisherman | P26: 1650 | Q26: 2 | R26: 1 | S26: 500 | T26: 55 | U26: 150 | V26: 2 | W26: Percent_of_lot | X26: 6 | Y26: 54 | Z26: 30 | AA26: 16 | AB26: Occasional | AC26: Some | AD26: Day-to-day price volatility | AE26: Irregular electricity and load-shedding | AF26: Transport cost increase
B27: M4-B-05 | C27: M4 | D27: 46087 | E27: Bepari | F27: Year_round | G27: 23 | H27: Primary | I27: 5 | J27: 8 | K27: Maund | L27: 298.56 | M27: 6 | N27: Kuakata | O27: Fisherman | P27: 1600 | Q27: 3 | R27: 3 | S27: 200 | T27: 115 | U27: 290 | V27: 3 | W27: Percent_of_lot | X27: 6 | Y27: 64 | Z27: 7 | AA27: 29 | AB27: Regular | AC27: Some | AD27: Irregular electricity and load-shedding | AE27: Waterlogging during monsoon | AF27: Low landings in lean season
B28: M4-B-06 | C28: M4
B29: M5-B-01 | C29: M5 | D29: 46088 | E29: Faria | F29: Seasonal | G29: 53 | H29: Primary | I29: 10 | J29: 1.3 | K29: Maund | L29: 48.52 | M29: 4 | N29: Fishery Ghat landing | O29: Aratdar | P29: 3000 | Q29: 3 | R29: 3 | S29: 250 | T29: 31 | U29: 110 | V29: 3 | W29: Percent_of_lot | X29: 6 | Y29: 63 | Z29: 29 | AA29: 8 | AB29: Occasional | AC29: Some | AD29: High ice price | AE29: Competition from frozen imported fish | AF29: Day-to-day price volatility
B30: M5-B-02 | C30: M5 | D30: 46088 | E30: Bepari | F30: Year_round | G30: 57 | H30: Secondary | I30: 35 | J30: 10 | K30: Maund | L30: 373.2 | M30: 3 | N30: Karnaphuli river ghat | O30: Aratdar | P30: 1750 | Q30: 3 | R30: 1 | S30: 150 | T30: 64 | U30: 210 | V30: 300 | W30: BDT_per_lot | X30: 5 | Y30: 56 | Z30: 25 | AA30: 19 | AB30: Occasional | AC30: Some | AD30: Supply syndicate control | AE30: Rising toll and lease burden | AF30: High ice price
B31: M5-B-03 | C31: M5 | D31: 46088 | E31: Bepari | F31: Year_round | G31: 49 | H31: Primary | I31: 28 | J31: 8 | K31: Maund | L31: 298.56 | M31: 6 | N31: Teknaf | O31: Fisherman | P31: 2800 | Q31: 2 | R31: 2 | S31: 350 | T31: 108 | U31: 300 | V31: 500 | W31: BDT_per_lot | X31: 7 | Y31: 72 | Z31: 21 | AA31: 7 | AB31: Regular | AC31: Some | AD31: High ice price | AE31: Waterlogging during monsoon | AF31: Rising cost of ice and salt
B32: M5-B-04 | C32: M5 | D32: 46088 | E32: Faria | F32: Seasonal | G32: 38 | H32: Primary | I32: 22 | J32: 1.9 | K32: Maund | L32: 70.91 | M32: 3 | N32: Moheshkhali | O32: Fisherman | P32: 2550 | Q32: 1 | R32: 1 | S32: 200 | T32: 31 | U32: 110 | V32: 1500 | W32: BDT_per_lot | X32: 3 | Y32: 54 | Z32: 28 | AA32: 18 | AB32: Occasional | AC32: Some | AD32: Rising toll and lease burden | AE32: Waterlogging during monsoon | AF32: Supply syndicate control
B33: M5-B-05 | C33: M5 | D33: 46088 | E33: Bepari | F33: Year_round | G33: 23 | H33: Primary | I33: 7 | J33: 4 | K33: Maund | L33: 149.28 | M33: 5 | N33: Bhola charter landing | O33: Aratdar | P33: 2250 | Q33: 2 | R33: 2 | S33: 250 | T33: 91 | U33: 330 | V33: 4 | W33: Percent_of_lot | X33: 8 | Y33: 59 | Z33: 9 | AA33: 32 | AB33: Occasional | AC33: None | AD33: High ice price | AE33: Low landings in lean season | AF33: Transport cost increase
B34: M5-B-06 | C34: M5
B35: M6-B-01 | C35: M6 | D35: 46084 | E35: Bepari | F35: Year_round | G35: 32 | H35: Illiterate | I35: 16 | J35: 9 | K35: Maund | L35: 335.88 | M35: 8 | N35: Fishery Ghat landing | O35: Faria | P35: 700 | Q35: 3 | R35: 1 | S35: 400 | T35: 33 | U35: 100 | V35: 2 | W35: Percent_of_lot | X35: 5 | Y35: 70 | Z35: 5 | AA35: 25 | AB35: Occasional | AC35: Some | AD35: Rising toll and lease burden | AE35: Supply syndicate control | AF35: Transport cost increase
B36: M6-B-02 | C36: M6 | D36: 46084 | E36: Bepari | F36: Seasonal | G36: 47 | H36: Secondary | I36: 13 | J36: 12 | K36: Maund | L36: 447.84 | M36: 3 | N36: Fishery Ghat landing | O36: Fisherman | P36: 1400 | Q36: 2 | R36: 2 | S36: 450 | T36: 67 | U36: 210 | V36: 3 | W36: Percent_of_lot | X36: 3 | Y36: 80 | Z36: 12 | AA36: 8 | AB36: Regular | AC36: Almost_all | AD36: Irregular electricity and load-shedding | AE36: Delayed credit recovery | AF36: Supply syndicate control
B37: M6-B-03 | C37: M6 | D37: 46084 | E37: Faria | F37: Seasonal | G37: 41 | H37: Secondary | I37: 14 | J37: 1.3 | K37: Maund | L37: 48.52 | M37: 3 | N37: Karnaphuli river ghat | O37: Fisherman | P37: 2550 | Q37: 1 | R37: 2 | S37: 350 | T37: 79 | U37: 210 | V37: 500 | W37: BDT_per_lot | X37: 8 | Y37: 62 | Z37: 25 | AA37: 13 | AB37: Never | AC37: Some | AD37: Day-to-day price volatility | AE37: Irregular electricity and load-shedding | AF37: Supply syndicate control
B38: M6-B-04 | C38: M6 | D38: 46084 | E38: Faria | F38: Year_round | G38: 53 | H38: Secondary | I38: 17 | J38: 1.8 | K38: Maund | L38: 67.18 | M38: 5 | N38: Karnaphuli river ghat | O38: Aratdar | P38: 2050 | Q38: 3 | R38: 3 | S38: 300 | T38: 95 | U38: 310 | V38: 300 | W38: BDT_per_lot | X38: 2 | Y38: 66 | Z38: 6 | AA38: 28 | AB38: Never | AC38: Some | AD38: High ice price | AE38: Transport cost increase | AF38: Unsold fish spoilage loss
B39: M6-B-05 | C39: M6 | D39: 46084 | E39: Faria | F39: Year_round | G39: 56 | H39: Secondary | I39: 11 | J39: 4 | K39: Maund | L39: 149.28 | M39: 7 | N39: Karnaphuli river ghat | O39: Fisherman | P39: 750 | Q39: 1 | R39: 3 | S39: 250 | T39: 96 | U39: 330 | V39: 3.5 | W39: Percent_of_lot | X39: 4 | Y39: 69 | Z39: 16 | AA39: 15 | AB39: Occasional | AC39: Some | AD39: Rising cost of ice and salt | AE39: Waterlogging during monsoon | AF39: Unsold fish spoilage loss
B40: M6-B-06 | C40: M6

Sheet Form_R_Khuchra
B2: Form R - Khuchra (Retail) Vendor Questionnaire (one respondent per row)
B4: Respondent_ID | C4: Market | D4: Interview_Date | E4: Age_years | F4: Education | G4: Years_in_business | H4: Daily_capacity_raw | I4: Daily_capacity_unit | J4: Daily_capacity_kg | K4: Family_members | L4: Shop_Van_Rent_BDT_per_day | M4: Ice_cost_BDT_per_day | N4: Wash_Water_Other_cost_BDT_per_day | O4: Spoilage_pct | P4: Buys_from | Q4: Sells_to | R4: Payment_cash_pct | S4: Payment_MFS_pct | T4: Payment_credit_pct | U4: MFS_transaction_frequency | V4: Sells_on_credit | W4: Problem_1 | X4: Problem_2 | Y4: Problem_3 | Z4: Pair_ID | AA4: Notes
B5: M1-R-01 | C5: M1 | D5: 46084 | E5: 55 | F5: Primary | G5: 6 | H5: 58 | I5: Kg | J5: 58 | K5: 5 | L5: 255 | M5: 185 | N5: 60 | O5: 3 | P5: Aratdar | Q5: Hawker | R5: 47 | S5: 41 | T5: 12 | U5: Occasional | V5: Some | W5: Competition from frozen imported fish | X5: Day-to-day price volatility | Y5: Rising toll and lease burden
B6: M1-R-02 | C6: M1 | D6: 46084 | E6: 31 | F6: Illiterate | G6: 15 | H6: 144 | I6: Kg | J6: 144 | K6: 2 | L6: 190 | M6: 150 | N6: 35 | O6: 4 | P6: Aratdar | Q6: Hawker | R6: 51 | S6: 15 | T6: 34 | U6: Occasional | V6: Some | W6: Transport cost increase | X6: Low landings in lean season | Y6: Supply syndicate control | Z6: PAIR-M1-02
B7: M1-R-03 | C7: M1 | D7: 46084 | E7: 33 | F7: Higher_Secondary | G7: 5 | H7: 43 | I7: Kg | J7: 43 | K7: 3 | L7: 245 | M7: 195 | N7: 105 | O7: 5 | P7: Aratdar | Q7: Household | R7: 69 | S7: 19 | T7: 12 | U7: Occasional | V7: Some | W7: Unsold fish spoilage loss | X7: Low landings in lean season | Y7: Delayed credit recovery
B8: M1-R-04 | C8: M1 | D8: 46084 | E8: 33 | F8: Secondary | G8: 6 | H8: 119 | I8: Kg | J8: 119 | K8: 7 | L8: 320 | M8: 105 | N8: 125 | O8: 8 | P8: Aratdar | Q8: Hotel | R8: 41 | S8: 40 | T8: 19 | U8: Occasional | V8: Almost_all | W8: Low landings in lean season | X8: Supply syndicate control | Y8: Rising toll and lease burden
B9: M1-R-05 | C9: M1 | D9: 46084 | E9: 43 | F9: Primary | G9: 3 | H9: 2.5 | I9: Maund | J9: 93.3 | K9: 7 | L9: 210 | M9: 170 | N9: 115 | O9: 8 | P9: Aratdar | Q9: Household | R9: 52 | S9: 28 | T9: 20 | U9: Occasional | V9: No | W9: Transport cost increase | X9: High ice price | Y9: Day-to-day price volatility | Z9: PAIR-M1-01
B10: M1-R-06 | C10: M1
B11: M2-R-01 | C11: M2 | D11: 46085 | E11: 30 | F11: Illiterate | G11: 4 | H11: 61 | I11: Kg | J11: 61 | K11: 8 | L11: 270 | M11: 230 | N11: 140 | O11: 5 | P11: Faria | Q11: Household | R11: 66 | S11: 27 | T11: 7 | U11: Occasional | V11: Some | W11: Waterlogging during monsoon | X11: Delayed credit recovery | Y11: Transport cost increase | Z11: PAIR-M2-03
B12: M2-R-02 | C12: M2 | D12: 46085 | E12: 40 | F12: Primary | G12: 22 | H12: 2.8 | I12: Maund | J12: 104.5 | K12: 2 | L12: 90 | M12: 205 | N12: 45 | O12: 3 | P12: Aratdar | Q12: Household | R12: 48 | S12: 36 | T12: 16 | U12: Regular | V12: Some | W12: Rising toll and lease burden | X12: Supply syndicate control | Y12: Delayed credit recovery
B13: M2-R-03 | C13: M2 | D13: 46085 | E13: 39 | F13: Primary | G13: 3 | H13: 2.7 | I13: Maund | J13: 100.76 | K13: 3 | L13: 330 | M13: 200 | N13: 70 | O13: 3 | P13: Aratdar | Q13: Institutional | R13: 49 | S13: 20 | T13: 31 | U13: Occasional | V13: Some | W13: Low landings in lean season | X13: Day-to-day price volatility | Y13: Waterlogging during monsoon | Z13: PAIR-M2-01
B14: M2-R-04 | C14: M2 | D14: 46085 | E14: 55 | F14: Primary | G14: 17 | H14: 2.8 | I14: Maund | J14: 104.5 | K14: 7 | L14: 265 | M14: 220 | N14: 30 | O14: 8 | P14: Fisherman | Q14: Hawker | R14: 55 | S14: 25 | T14: 20 | U14: Regular | V14: No | W14: Competition from frozen imported fish | X14: Day-to-day price volatility | Y14: Low landings in lean season
B15: M2-R-05 | C15: M2 | D15: 46085 | E15: 27 | F15: Secondary | G15: 6 | H15: 2.7 | I15: Maund | J15: 100.76 | K15: 6 | L15: 300 | M15: 175 | N15: 85 | O15: 6 | P15: Fisherman | Q15: Household | R15: 69 | S15: 15 | T15: 16 | U15: Regular | V15: No | W15: Rising cost of ice and salt | X15: Unsold fish spoilage loss | Y15: Delayed credit recovery | Z15: PAIR-M2-02
B16: M2-R-06 | C16: M2
B17: M3-R-01 | C17: M3 | D17: 46086 | E17: 51 | F17: Secondary | G17: 25 | H17: 150 | I17: Kg | J17: 150 | K17: 8 | L17: 115 | M17: 195 | N17: 60 | O17: 6 | P17: Fisherman | Q17: Hotel | R17: 52 | S17: 36 | T17: 12 | U17: Regular | V17: No | W17: Waterlogging during monsoon | X17: Competition from frozen imported fish | Y17: Unsold fish spoilage loss
B18: M3-R-02 | C18: M3 | D18: 46086 | E18: 26 | F18: Primary | G18: 4 | H18: 2 | I18: Maund | J18: 74.64 | K18: 8 | L18: 155 | M18: 240 | N18: 30 | O18: 4 | P18: Aratdar | Q18: Household | R18: 56 | S18: 29 | T18: 15 | U18: Occasional | V18: Some | W18: Waterlogging during monsoon | X18: Rising toll and lease burden | Y18: Unsold fish spoilage loss
B19: M3-R-03 | C19: M3 | D19: 46086 | E19: 53 | F19: Secondary | G19: 9 | H19: 143 | I19: Kg | J19: 143 | K19: 3 | L19: 235 | M19: 210 | N19: 100 | O19: 6 | P19: Aratdar | Q19: Hotel | R19: 56 | S19: 38 | T19: 6 | U19: Regular | V19: Some | W19: Waterlogging during monsoon | X19: Delayed credit recovery | Y19: High ice price | Z19: PAIR-M3-01
B20: M3-R-04 | C20: M3 | D20: 46086 | E20: 40 | F20: Secondary | G20: 2 | H20: 135 | I20: Kg | J20: 135 | K20: 4 | L20: 200 | M20: 185 | N20: 105 | O20: 5 | P20: Aratdar | Q20: Institutional | R20: 54 | S20: 30 | T20: 16 | U20: Regular | V20: Some | W20: Day-to-day price volatility | X20: Rising cost of ice and salt | Y20: Low landings in lean season | Z20: PAIR-M3-02
B21: M3-R-05 | C21: M3 | D21: 46086 | E21: 21 | F21: Higher_Secondary | G21: 5 | H21: 137 | I21: Kg | J21: 137 | K21: 6 | L21: 290 | M21: 90 | N21: 30 | O21: 7 | P21: Aratdar | Q21: Household | R21: 41 | S21: 31 | T21: 28 | U21: Occasional | V21: Some | W21: High ice price | X21: Waterlogging during monsoon | Y21: Day-to-day price volatility
B22: M3-R-06 | C22: M3
B23: M4-R-01 | C23: M4 | D23: 46087 | E23: 27 | F23: Primary | G23: 11 | H23: 1.8 | I23: Maund | J23: 67.18 | K23: 7 | L23: 285 | M23: 240 | N23: 80 | O23: 5 | P23: Aratdar | Q23: Household | R23: 62 | S23: 27 | T23: 11 | U23: Regular | V23: Some | W23: Competition from frozen imported fish | X23: Day-to-day price volatility | Y23: Irregular electricity and load-shedding | Z23: PAIR-M4-01
B24: M4-R-02 | C24: M4 | D24: 46087 | E24: 34 | F24: Secondary | G24: 18 | H24: 60 | I24: Kg | J24: 60 | K24: 8 | L24: 140 | M24: 130 | N24: 90 | O24: 6 | P24: Aratdar | Q24: Institutional | R24: 57 | S24: 17 | T24: 26 | U24: Regular | V24: Some | W24: Delayed credit recovery | X24: Day-to-day price volatility | Y24: Supply syndicate control | Z24: PAIR-M4-03
B25: M4-R-03 | C25: M4 | D25: 46087 | E25: 53 | F25: Primary | G25: 27 | H25: 139 | I25: Kg | J25: 139 | K25: 6 | L25: 145 | M25: 140 | N25: 115 | O25: 8 | P25: Aratdar | Q25: Household | R25: 44 | S25: 40 | T25: 16 | U25: Regular | V25: Almost_all | W25: Day-to-day price volatility | X25: Low landings in lean season | Y25: Transport cost increase
B26: M4-R-04 | C26: M4 | D26: 46087 | E26: 25 | F26: Secondary | G26: 5 | H26: 47 | I26: Kg | J26: 47 | K26: 8 | L26: 225 | M26: 215 | N26: 115 | O26: 4 | P26: Aratdar | Q26: Household | R26: 44 | S26: 15 | T26: 41 | U26: Regular | V26: Some | W26: Competition from frozen imported fish | X26: Rising cost of ice and salt | Y26: Supply syndicate control
B27: M4-R-05 | C27: M4 | D27: 46087 | E27: 40 | F27: Primary | G27: 13 | H27: 136 | I27: Kg | J27: 136 | K27: 8 | L27: 265 | M27: 120 | N27: 45 | O27: 3 | P27: Aratdar | Q27: Household | R27: 68 | S27: 19 | T27: 13 | U27: Never | V27: Some | W27: Unsold fish spoilage loss | X27: Transport cost increase | Y27: Delayed credit recovery | Z27: PAIR-M4-02
B28: M4-R-06 | C28: M4
B29: M5-R-01 | C29: M5 | D29: 46088 | E29: 34 | F29: Illiterate | G29: 9 | H29: 106 | I29: Kg | J29: 106 | K29: 4 | L29: 120 | M29: 100 | N29: 145 | O29: 6 | P29: Aratdar | Q29: Other | R29: 54 | S29: 21 | T29: 25 | U29: Regular | V29: Some | W29: Transport cost increase | X29: High ice price | Y29: Rising cost of ice and salt | Z29: PAIR-M5-03
B30: M5-R-02 | C30: M5 | D30: 46088 | E30: 27 | F30: Secondary | G30: 11 | H30: 56 | I30: Kg | J30: 56 | K30: 3 | L30: 300 | M30: 100 | N30: 40 | O30: 7 | P30: Other | Q30: Household | R30: 44 | S30: 43 | T30: 13 | U30: Regular | V30: Some | W30: Rising cost of ice and salt | X30: Irregular electricity and load-shedding | Y30: Low landings in lean season | Z30: PAIR-M5-02
B31: M5-R-03 | C31: M5 | D31: 46088 | E31: 50 | F31: Secondary | G31: 20 | H31: 64 | I31: Kg | J31: 64 | K31: 3 | L31: 315 | M31: 160 | N31: 45 | O31: 4 | P31: Aratdar | Q31: Hotel | R31: 48 | S31: 32 | T31: 20 | U31: Occasional | V31: Some | W31: Unsold fish spoilage loss | X31: Low landings in lean season | Y31: High ice price
B32: M5-R-04 | C32: M5 | D32: 46088 | E32: 43 | F32: Illiterate | G32: 14 | H32: 64 | I32: Kg | J32: 64 | K32: 4 | L32: 350 | M32: 105 | N32: 115 | O32: 8 | P32: Aratdar | Q32: Hawker | R32: 63 | S32: 16 | T32: 21 | U32: Never | V32: Almost_all | W32: Rising cost of ice and salt | X32: Irregular electricity and load-shedding | Y32: Transport cost increase | Z32: PAIR-M5-01
B33: M5-R-05 | C33: M5 | D33: 46088 | E33: 35 | F33: Primary | G33: 8 | H33: 115 | I33: Kg | J33: 115 | K33: 6 | L33: 110 | M33: 165 | N33: 135 | O33: 8 | P33: Aratdar | Q33: Household | R33: 63 | S33: 30 | T33: 7 | U33: Occasional | V33: Some | W33: Rising toll and lease burden | X33: Day-to-day price volatility | Y33: Unsold fish spoilage loss
B34: M5-R-06 | C34: M5
B35: M6-R-01 | C35: M6 | D35: 46084 | E35: 47 | F35: Higher_Secondary | G35: 28 | H35: 56 | I35: Kg | J35: 56 | K35: 8 | L35: 80 | M35: 100 | N35: 125 | O35: 3 | P35: Aratdar | Q35: Household | R35: 48 | S35: 22 | T35: 30 | U35: Occasional | V35: Some | W35: Transport cost increase | X35: Day-to-day price volatility | Y35: Rising cost of ice and salt | Z35: PAIR-M6-01
B36: M6-R-02 | C36: M6 | D36: 46084 | E36: 32 | F36: Primary | G36: 12 | H36: 2.8 | I36: Maund | J36: 104.5 | K36: 6 | L36: 85 | M36: 185 | N36: 80 | O36: 7 | P36: Fisherman | Q36: Household | R36: 67 | S36: 28 | T36: 5 | U36: Regular | V36: No | W36: Transport cost increase | X36: High ice price | Y36: Unsold fish spoilage loss
B37: M6-R-03 | C37: M6 | D37: 46084 | E37: 38 | F37: Secondary | G37: 12 | H37: 116 | I37: Kg | J37: 116 | K37: 4 | L37: 70 | M37: 135 | N37: 60 | O37: 5 | P37: Aratdar | Q37: Other | R37: 62 | S37: 15 | T37: 23 | U37: Regular | V37: Some | W37: Irregular electricity and load-shedding | X37: Transport cost increase | Y37: Delayed credit recovery
B38: M6-R-04 | C38: M6 | D38: 46084 | E38: 47 | F38: Illiterate | G38: 16 | H38: 44 | I38: Kg | J38: 44 | K38: 2 | L38: 180 | M38: 250 | N38: 30 | O38: 3 | P38: Faria | Q38: Household | R38: 64 | S38: 30 | T38: 6 | U38: Never | V38: Some | W38: High ice price | X38: Supply syndicate control | Y38: Rising toll and lease burden | Z38: PAIR-M6-02
B39: M6-R-05 | C39: M6 | D39: 46084 | E39: 50 | F39: Secondary | G39: 7 | H39: 135 | I39: Kg | J39: 135 | K39: 7 | L39: 295 | M39: 245 | N39: 70 | O39: 8 | P39: Fisherman | Q39: Hotel | R39: 59 | S39: 36 | T39: 5 | U39: Occasional | V39: Almost_all | W39: Transport cost increase | X39: Day-to-day price volatility | Y39: Rising cost of ice and salt
B40: M6-R-06 | C40: M6

Sheet Form_C_Consumer
B2: Form C - Fish Buyer Exit Slip (one respondent per row)
B4: Respondent_ID | C4: Market | D4: Interview_Date | E4: Interview_time | F4: Consent_given | G4: Visit_frequency | H4: Visit_interval_days | I4: Payment_method | J4: Main_reason_choosing_arat | K4: Pair_ID | L4: Notes
B5: M1-C-01 | C5: M1 | D5: 46084 | E5: 09:45 | F5: Yes | G5: Daily | H5: 1 | I5: Cash | J5: Purity
B6: M1-C-02 | C6: M1 | D6: 46084 | E6: 12:05 | F6: Yes | G6: Weekly | H6: 7 | I6: Nagad_app | J6: Purity
B7: M1-C-03 | C7: M1 | D7: 46084 | E7: 09:55 | F7: Yes | G7: Weekly | H7: 5 | I7: Credit | J7: Purity
B8: M1-C-04 | C8: M1 | D8: 46084 | E8: 09:30 | F8: Yes | G8: Weekly | H8: 5 | I8: Cash | J8: Price
B9: M1-C-05 | C9: M1 | D9: 46084 | E9: 12:05 | F9: Yes | G9: Weekly | H9: 7 | I9: bKash | J9: Price
B10: M1-C-06 | C10: M1
B11: M2-C-01 | C11: M2 | D11: 46085 | E11: 12:25 | F11: Yes | G11: Daily | H11: 2 | I11: Cash | J11: Purity
B12: M2-C-02 | C12: M2 | D12: 46085 | E12: 11:50 | F12: Yes | G12: Weekly | H12: 7 | I12: Cash | J12: Proximity
B13: M2-C-03 | C13: M2 | D13: 46085 | E13: 09:15 | F13: Yes | G13: Daily | H13: 2 | I13: bKash | J13: Familiar_shop
B14: M2-C-04 | C14: M2 | D14: 46085 | E14: 09:25 | F14: Yes | G14: Weekly | H14: 7 | I14: Nagad_app | J14: Purity
B15: M2-C-05 | C15: M2 | D15: 46085 | E15: 08:45 | F15: Yes | G15: Daily | H15: 2 | I15: Cash | J15: Price
B16: M2-C-06 | C16: M2
B17: M3-C-01 | C17: M3 | D17: 46086 | E17: 09:15 | F17: Yes | G17: Daily | H17: 2 | I17: Cash | J17: Purity
B18: M3-C-02 | C18: M3 | D18: 46086 | E18: 09:15 | F18: Yes | G18: Weekly | H18: 4 | I18: Cash | J18: Familiar_shop
B19: M3-C-03 | C19: M3 | D19: 46086 | E19: 12:25 | F19: Yes | G19: Weekly | H19: 5 | I19: Cash | J19: Familiar_shop
B20: M3-C-04 | C20: M3 | D20: 46086 | E20: 09:45 | F20: Yes | G20: Weekly | H20: 6 | I20: Credit | J20: Familiar_shop
B21: M3-C-05 | C21: M3 | D21: 46086 | E21: 09:30 | F21: Yes | G21: Daily | H21: 1 | I21: Cash | J21: Proximity
B22: M3-C-06 | C22: M3
B23: M4-C-01 | C23: M4 | D23: 46087 | E23: 10:40 | F23: Yes | G23: Weekly | H23: 6 | I23: Nagad_app | J23: Proximity
B24: M4-C-02 | C24: M4 | D24: 46087 | E24: 08:35 | F24: Yes | G24: Weekly | H24: 5 | I24: Cash | J24: Variety
B25: M4-C-03 | C25: M4 | D25: 46087 | E25: 08:50 | F25: Yes | G25: Weekly | H25: 7 | I25: bKash | J25: Familiar_shop
B26: M4-C-04 | C26: M4 | D26: 46087 | E26: 08:40 | F26: Yes | G26: Daily | H26: 2 | I26: Cash | J26: Other
B27: M4-C-05 | C27: M4 | D27: 46087 | E27: 09:50 | F27: Yes | G27: Weekly | H27: 7 | I27: bKash | J27: Purity
B28: M4-C-06 | C28: M4
B29: M5-C-01 | C29: M5 | D29: 46088 | E29: 11:45 | F29: Yes | G29: Daily | H29: 2 | I29: Nagad_app | J29: Purity
B30: M5-C-02 | C30: M5 | D30: 46088 | E30: 12:20 | F30: Yes | G30: Weekly | H30: 5 | I30: Cash | J30: Purity
B31: M5-C-03 | C31: M5 | D31: 46088 | E31: 09:15 | F31: Yes | G31: Weekly | H31: 4 | I31: Nagad_app | J31: Purity
B32: M5-C-04 | C32: M5 | D32: 46088 | E32: 08:30 | F32: Yes | G32: Weekly | H32: 5 | I32: Cash | J32: Proximity
B33: M5-C-05 | C33: M5 | D33: 46088 | E33: 10:15 | F33: Yes | G33: Weekly | H33: 7 | I33: Nagad_app | J33: Price
B34: M5-C-06 | C34: M5
B35: M6-C-01 | C35: M6 | D35: 46084 | E35: 10:25 | F35: Yes | G35: Weekly | H35: 6 | I35: bKash | J35: Price
B36: M6-C-02 | C36: M6 | D36: 46084 | E36: 08:10 | F36: Yes | G36: Weekly | H36: 4 | I36: bKash | J36: Proximity
B37: M6-C-03 | C37: M6 | D37: 46084 | E37: 12:15 | F37: Yes | G37: Weekly | H37: 6 | I37: Cash | J37: Other
B38: M6-C-04 | C38: M6 | D38: 46084 | E38: 08:00 | F38: Yes | G38: Weekly | H38: 7 | I38: Nagad_app | J38: Purity
B39: M6-C-05 | C39: M6 | D39: 46084 | E39: 09:55 | F39: Yes | G39: Weekly | H39: 4 | I39: Cash | J39: Familiar_shop
B40: M6-C-06 | C40: M6

Sheet Price_Observations
B2: Price Observations - one row per respondent x species quote (core dataset)
B4: Obs_ID | C4: Respondent_ID | D4: Market | E4: Actor_type | F4: Species_code | G4: Buy_price_raw | H4: Sell_price_raw | I4: Unit | J4: Buy_BDT_per_kg | K4: Sell_BDT_per_kg | L4: Quantity_raw | M4: Quantity_unit | N4: Quantity_kg | O4: Pair_ID | P4: Notes
B5: PO-0001 | C5: M1-A-01 | D5: M1 | E5: Aratdar | F5: S01 | G5: 36750 | H5: 38500 | I5: Maund | J5: 984.73 | K5: 1031.62 | L5: 3.6 | M5: Maund | N5: 134.35
B6: PO-0002 | C6: M1-A-01 | D6: M1 | E6: Aratdar | F6: S02 | G6: 43000 | H6: 45000 | I6: Maund | J6: 1152.2 | K6: 1205.79 | L6: 4 | M6: Maund | N6: 149.28
B7: PO-0003 | C7: M1-A-01 | D7: M1 | E7: Aratdar | F7: S05 | G7: 14750 | H7: 15500 | I7: Maund | J7: 395.23 | K7: 415.33 | L7: 2.6 | M7: Maund | N7: 97.03
B8: PO-0004 | C8: M1-A-01 | D8: M1 | E8: Aratdar | F8: S06 | G8: 12250 | H8: 13000 | I8: Maund | J8: 328.24 | K8: 348.34 | L8: 3.7 | M8: Maund | N8: 138.08 | O8: PAIR-M1-02
B9: PO-0005 | C9: M1-A-01 | D9: M1 | E9: Aratdar | F9: S09 | G9: 7400 | H9: 7700 | I9: Maund | J9: 198.29 | K9: 206.32 | L9: 3 | M9: Maund | N9: 111.96
B10: PO-0006 | C10: M1-A-01 | D10: M1 | E10: Aratdar | F10: S07 | G10: K | H10: K | P10: Species not handled today
B11: PO-0007 | C11: M1-A-01 | D11: M1 | E11: Aratdar | F11: S03 | G11: K | H11: K | P11: Species not handled today
B12: PO-0008 | C12: M1-A-02 | D12: M1 | E12: Aratdar | F12: S01 | G12: 37750 | H12: 39500 | I12: Maund | J12: 1011.52 | K12: 1058.41 | L12: 3.6 | M12: Maund | N12: 134.35
B13: PO-0009 | C13: M1-A-02 | D13: M1 | E13: Aratdar | F13: S03 | G13: 28250 | H13: 29750 | I13: Maund | J13: 756.97 | K13: 797.16 | L13: 4.6 | M13: Maund | N13: 171.67
B14: PO-0010 | C14: M1-A-02 | D14: M1 | E14: Aratdar | F14: S04 | G14: 24000 | H14: 24750 | I14: Maund | J14: 643.09 | K14: 663.18 | L14: 3.3 | M14: Maund | N14: 123.16
B15: PO-0011 | C15: M1-A-02 | D15: M1 | E15: Aratdar | F15: S05 | G15: 15000 | H15: 15500 | I15: Maund | J15: 401.93 | K15: 415.33 | L15: 2.9 | M15: Maund | N15: 108.23
B16: PO-0012 | C16: M1-A-02 | D16: M1 | E16: Aratdar | F16: S06 | G16: 11750 | H16: 12000 | I16: Maund | J16: 314.84 | K16: 321.54 | L16: 3.2 | M16: Maund | N16: 119.42
B17: PO-0013 | C17: M1-A-02 | D17: M1 | E17: Aratdar | F17: S02 | G17: K | H17: K | P17: Species not handled today
B18: PO-0014 | C18: M1-A-02 | D18: M1 | E18: Aratdar | F18: S09 | G18: K | H18: K | P18: Species not handled today
